Watching for file changes with StatReloader
Exception in thread django-main-thread:
Traceback (most recent call last):
  File "/usr/lib/python3.12/threading.py", line 1073, in _bootstrap_inner
    self.run()
  File "/usr/lib/python3.12/threading.py", line 1010, in run
    self._target(*self._args, **self._kwargs)
  File "/var/www/div_app/div_env/lib/python3.12/site-packages/django/utils/autoreload.py", line 64, in wrapper
    fn(*args, **kwargs)
  File "/var/www/div_app/div_env/lib/python3.12/site-packages/django/core/management/commands/runserver.py", line 133, in inner_run
    self.check(display_num_errors=True)
  File "/var/www/div_app/div_env/lib/python3.12/site-packages/django/core/management/base.py", line 485, in check
    all_issues = checks.run_checks(
                 ^^^^^^^^^^^^^^^^^^
  File "/var/www/div_app/div_env/lib/python3.12/site-packages/django/core/checks/registry.py", line 88, in run_checks
    new_errors = check(app_configs=app_configs, databases=databases)
                 ^^^^^^^^^^^^^^^^^^^^^^^^^^^^^^^^^^^^^^^^^^^^^^^^^^^
  File "/var/www/div_app/div_env/lib/python3.12/site-packages/django/core/checks/urls.py", line 14, in check_url_config
    return check_resolver(resolver)
           ^^^^^^^^^^^^^^^^^^^^^^^^
  File "/var/www/div_app/div_env/lib/python3.12/site-packages/django/core/checks/urls.py", line 24, in check_resolver
    return check_method()
           ^^^^^^^^^^^^^^
  File "/var/www/div_app/div_env/lib/python3.12/site-packages/django/urls/resolvers.py", line 494, in check
    for pattern in self.url_patterns:
                   ^^^^^^^^^^^^^^^^^
  File "/var/www/div_app/div_env/lib/python3.12/site-packages/django/utils/functional.py", line 57, in __get__
    res = instance.__dict__[self.name] = self.func(instance)
                                         ^^^^^^^^^^^^^^^^^^^
  File "/var/www/div_app/div_env/lib/python3.12/site-packages/django/urls/resolvers.py", line 715, in url_patterns
    patterns = getattr(self.urlconf_module, "urlpatterns", self.urlconf_module)
                       ^^^^^^^^^^^^^^^^^^^
  File "/var/www/div_app/div_env/lib/python3.12/site-packages/django/utils/functional.py", line 57, in __get__
    res = instance.__dict__[self.name] = self.func(instance)
                                         ^^^^^^^^^^^^^^^^^^^
  File "/var/www/div_app/div_env/lib/python3.12/site-packages/django/urls/resolvers.py", line 708, in urlconf_module
    return import_module(self.urlconf_name)
           ^^^^^^^^^^^^^^^^^^^^^^^^^^^^^^^^
  File "/usr/lib/python3.12/importlib/__init__.py", line 90, in import_module
    return _bootstrap._gcd_import(name[level:], package, level)
           ^^^^^^^^^^^^^^^^^^^^^^^^^^^^^^^^^^^^^^^^^^^^^^^^^^^^
  File "<frozen importlib._bootstrap>", line 1387, in _gcd_import
  File "<frozen importlib._bootstrap>", line 1360, in _find_and_load
  File "<frozen importlib._bootstrap>", line 1331, in _find_and_load_unlocked
  File "<frozen importlib._bootstrap>", line 935, in _load_unlocked
  File "<frozen importlib._bootstrap_external>", line 995, in exec_module
  File "<frozen importlib._bootstrap>", line 488, in _call_with_frames_removed
  File "/var/www/div_app/div_config/urls.py", line 18, in <module>
    from div_content.views.blog import blog_add_post, blog_detail, blog_index, blog_list, blog_new, blog_post_detail, blog_section_detail
  File "/var/www/div_app/div_content/views/blog.py", line 13, in <module>
  File "/var/www/div_app/div_content/forms/blog.py", line 14
    'content': forms.Textarea(attrs={'rows': 3, 'placeholder': 'Napi�te sv�j koment��...'}),
                                                               ^^^^^^^^^^^^^^^^^^^^
SyntaxError: (unicode error) 'utf-8' codec can't decode byte 0x9a in position 4: invalid start byte
/var/www/div_app/div_content/forms/blog.py changed, reloading.
Performing system checks...

Watching for file changes with StatReloader
Error: That port is already in use.
